INFO: Default loss without VGG
INFO: No cutoff
INFO: 2023-08-21 13:42:40 Argument batch_size: 8
INFO: 2023-08-21 13:42:40 Argument code_test: True
INFO: 2023-08-21 13:42:40 Argument data_train_path: ./../data/data_96/train/
INFO: 2023-08-21 13:42:40 Argument data_val_path: ./..data/data_96/val/data_val_chr19_96.npy
INFO: 2023-08-21 13:42:40 Argument device_number: 1
INFO: 2023-08-21 13:42:40 Argument epoch: 1
INFO: 2023-08-21 13:42:40 Argument local_rank: 0
INFO: 2023-08-21 13:42:40 Argument loss: single_channel_no_vgg
INFO: 2023-08-21 13:42:40 Argument max_HiC: 255
INFO: 2023-08-21 13:42:40 Argument num_gpu: 1
INFO: 2023-08-21 13:42:40 Argument num_workers: 1
INFO: 2023-08-21 13:42:40 Argument patch_size: 96
INFO: 2023-08-21 13:42:40 Argument resume_epoch: 0
INFO: 2023-08-21 13:42:40 Argument resume_path: None
INFO: 2023-08-21 13:42:40 Argument rgb: False
INFO: 2023-08-21 13:42:40 Argument train_dataset: hic
INFO: 2023-08-21 13:42:40 Argument val_datasets: ['hic']
INFO: 2023-08-21 13:42:46 epoch:0 dataset: 1/17 step: 0/155 time:0.57+3.17 loss_avg:2.2300e-01
INFO: 2023-08-21 13:42:47 epoch:0 dataset: 1/17 step: 1/155 time:0.00+0.88 loss_avg:1.8877e-01
INFO: Training on data_train_chr7_96.npy complete.
INFO: 2023-08-21 13:42:49 epoch:0 dataset: 2/17 step: 0/90 time:1.21+0.86 loss_avg:2.5133e-01
INFO: 2023-08-21 13:42:49 epoch:0 dataset: 2/17 step: 1/90 time:0.00+0.85 loss_avg:2.4228e-01
INFO: Traceback:
INFO: Traceback (most recent call last):
  File "./train_1d.py", line 314, in <module>
    train(model, args)
  File "./train_1d.py", line 201, in train
    val_dataset = np.load(data_val_path)
  File "/usr/local/lib/python3.8/dist-packages/numpy/lib/npyio.py", line 405, in load
    fid = stack.enter_context(open(os_fspath(file), "rb"))
FileNotFoundError: [Errno 2] No such file or directory: './..data/data_96/val/data_val_chr19_96.npy'

INFO: Sys.exc_info()[2]:
INFO: <traceback object at 0x7fdac9b2aac0>
